<?xml version="1.0" encoding="utf-8"?>
<!-- This URDF was automatically created by SolidWorks to URDF Exporter! Originally created by Stephen Brawner (brawner@gmail.com) 
     Commit Version: 1.6.0-4-g7f85cfe  Build Version: 1.6.7995.38578
     For more information, please see http://wiki.ros.org/sw_urdf_exporter -->
<robot
  name="real_robot_urdf">
  <link
    name="base_link">
    <inertial>
      <origin
        xyz="0.00047472 6.9315E-06 0.018436"
        rpy="0 0 0" />
      <mass
        value="0.70951" />
      <inertia
        ixx="0.0011478"
        ixy="-4.6822E-08"
        ixz="-2.9441E-07"
        iyy="0.0011755"
        iyz="7.868E-08"
        izz="0.0021505" />
    </inertial>
    <visual>
      <origin
        xyz="0 0 0"
        rpy="0 0 0" />
      <geometry>
        <mesh
          filename="package://real_robot_urdf/meshes/base_link.STL" />
      </geometry>
      <material
        name="">
        <color
          rgba="0.75686 0.76863 0.75294 1" />
      </material>
    </visual>
    <collision>
      <origin
        xyz="0 0 0"
        rpy="0 0 0" />
      <geometry>
        <mesh
          filename="package://real_robot_urdf/meshes/base_link.STL" />
      </geometry>
    </collision>
  </link>
  <link
    name="forearm_link">
    <inertial>
      <origin
        xyz="0.0023542 0.0085726 0.12447"
        rpy="0 0 0" />
      <mass
        value="3.4311" />
      <inertia
        ixx="0.011117"
        ixy="-0.0001688"
        ixz="-0.0002995"
        iyy="0.010549"
        iyz="-0.0010909"
        izz="0.010872" />
    </inertial>
    <visual>
      <origin
        xyz="0 0 0"
        rpy="0 0 0" />
      <geometry>
        <mesh
          filename="package://real_robot_urdf/meshes/forearm_link.STL" />
      </geometry>
      <material
        name="">
        <color
          rgba="0.75686 0.76863 0.75294 1" />
      </material>
    </visual>
    <collision>
      <origin
        xyz="0 0 0"
        rpy="0 0 0" />
      <geometry>
        <mesh
          filename="package://real_robot_urdf/meshes/forearm_link.STL" />
      </geometry>
    </collision>
  </link>
  <joint
    name="elbow_joint"
    type="revolute">
    <origin
      xyz="0 0 0"
      rpy="0 0 0" />
    <parent
      link="base_link" />
    <child
      link="forearm_link" />
    <axis
      xyz="0 0 1" />
    <limit
      lower="0"
      upper="3.142"
      effort="300"
      velocity="3" />
  </joint>
  <link
    name="upper_arm_link">
    <inertial>
      <origin
        xyz="2.6374E-05 0.28803 0.064081"
        rpy="0 0 0" />
      <mass
        value="5.766" />
      <inertia
        ixx="0.053593"
        ixy="-1.3385E-05"
        ixz="4.9362E-06"
        iyy="0.0077952"
        iyz="2.3286E-07"
        izz="0.053877" />
    </inertial>
    <visual>
      <origin
        xyz="0 0 0"
        rpy="0 0 0" />
      <geometry>
        <mesh
          filename="package://real_robot_urdf/meshes/upper_arm_link.STL" />
      </geometry>
      <material
        name="">
        <color
          rgba="0.75686 0.76863 0.75294 1" />
      </material>
    </visual>
    <collision>
      <origin
        xyz="0 0 0"
        rpy="0 0 0" />
      <geometry>
        <mesh
          filename="package://real_robot_urdf/meshes/upper_arm_link.STL" />
      </geometry>
    </collision>
  </link>
  <joint
    name="shoulder_lift_joint"
    type="revolute">
    <origin
      xyz="0.057348 0.2089 0.13048"
      rpy="1.5708 0 -0.26793" />
    <parent
      link="forearm_link" />
    <child
      link="upper_arm_link" />
    <axis
      xyz="0 0 -1" />
    <limit
      lower="-1.57"
      upper="1.57"
      effort="200"
      velocity="3" />
  </joint>
  <link
    name="shoulder_link">
    <inertial>
      <origin
        xyz="0.24626 0.00038792 -0.064902"
        rpy="0 0 0" />
      <mass
        value="4.9784" />
      <inertia
        ixx="0.0058504"
        ixy="6.6369E-09"
        ixz="-0.00020001"
        iyy="0.051562"
        iyz="-1.5261E-08"
        izz="0.051782" />
    </inertial>
    <visual>
      <origin
        xyz="0 0 0"
        rpy="0 0 0" />
      <geometry>
        <mesh
          filename="package://real_robot_urdf/meshes/shoulder_link.STL" />
      </geometry>
      <material
        name="">
        <color
          rgba="0.75686 0.76863 0.75294 1" />
      </material>
    </visual>
    <collision>
      <origin
        xyz="0 0 0"
        rpy="0 0 0" />
      <geometry>
        <mesh
          filename="package://real_robot_urdf/meshes/shoulder_link.STL" />
      </geometry>
    </collision>
  </link>
  <joint
    name="shoulder_pan_joint"
    type="revolute">
    <origin
      xyz="0.013053 0.58103 0.25475"
      rpy="0 0.034793 0" />
    <parent
      link="upper_arm_link" />
    <child
      link="shoulder_link" />
    <axis
      xyz="0 0 -1" />
    <limit
      lower="-1.57"
      upper="1.57"
      effort="200"
      velocity="3" />
  </joint>
  <link
    name="wrist_1_link">
    <inertial>
      <origin
        xyz="0.038757 0.0032123 -0.16106"
        rpy="0 0 0" />
      <mass
        value="0.83842" />
      <inertia
        ixx="0.0010339"
        ixy="-3.0338E-05"
        ixz="1.6348E-05"
        iyy="0.0009644"
        iyz="0.00012774"
        izz="0.00096895" />
    </inertial>
    <visual>
      <origin
        xyz="0 0 0"
        rpy="0 0 0" />
      <geometry>
        <mesh
          filename="package://real_robot_urdf/meshes/wrist_1_link.STL" />
      </geometry>
      <material
        name="">
        <color
          rgba="0.75686 0.76863 0.75294 1" />
      </material>
    </visual>
    <collision>
      <origin
        xyz="0 0 0"
        rpy="0 0 0" />
      <geometry>
        <mesh
          filename="package://real_robot_urdf/meshes/wrist_1_link.STL" />
      </geometry>
    </collision>
  </link>
  <joint
    name="wrist_1_joint"
    type="revolute">
    <origin
      xyz="0.56474 0.000388 -0.0090716"
      rpy="0 0.23313 0" />
    <parent
      link="shoulder_link" />
    <child
      link="wrist_1_link" />
    <axis
      xyz="-0.23103 0 0.97295" />
    <limit
      lower="-1.57"
      upper="1.57"
      effort="200"
      velocity="3" />
  </joint>
  <link
    name="wrist_2_link">
    <inertial>
      <origin
        xyz="0.0034039 0.00048525 0.16585"
        rpy="0 0 0" />
      <mass
        value="0.83842" />
      <inertia
        ixx="0.00096592"
        ixy="1.045E-05"
        ixz="-0.00012992"
        iyy="0.0010363"
        iyz="1.8899E-05"
        izz="0.00096507" />
    </inertial>
    <visual>
      <origin
        xyz="0 0 0"
        rpy="0 0 0" />
      <geometry>
        <mesh
          filename="package://real_robot_urdf/meshes/wrist_2_link.STL" />
      </geometry>
      <material
        name="">
        <color
          rgba="0.75686 0.76863 0.75294 1" />
      </material>
    </visual>
    <collision>
      <origin
        xyz="0 0 0"
        rpy="0 0 0" />
      <geometry>
        <mesh
          filename="package://real_robot_urdf/meshes/wrist_2_link.STL" />
      </geometry>
    </collision>
  </link>
  <joint
    name="wrist_2_joint"
    type="revolute">
    <origin
      xyz="0.039855 -0.05588 -0.16569"
      rpy="-1.5708 0 0" />
    <parent
      link="wrist_1_link" />
    <child
      link="wrist_2_link" />
    <axis
      xyz="0 0 -1" />
    <limit
      lower="-1.57"
      upper="1.57"
      effort="100"
      velocity="2" />
  </joint>
  <link
    name="wrist_3_link">
    <inertial>
      <origin
        xyz="0.00017986 -4.4952E-05 -0.13062"
        rpy="0 0 0" />
      <mass
        value="0.15932" />
      <inertia
        ixx="8.2239E-05"
        ixy="1.0723E-06"
        ixz="8.7279E-08"
        iyy="8.7571E-05"
        iyz="4.5096E-07"
        izz="0.00014976" />
    </inertial>
    <visual>
      <origin
        xyz="0 0 0"
        rpy="0 0 0" />
      <geometry>
        <mesh
          filename="package://real_robot_urdf/meshes/wrist_3_link.STL" />
      </geometry>
      <material
        name="">
        <color
          rgba="0.75686 0.76863 0.75294 1" />
      </material>
    </visual>
    <collision>
      <origin
        xyz="0 0 0"
        rpy="0 0 0" />
      <geometry>
        <mesh
          filename="package://real_robot_urdf/meshes/wrist_3_link.STL" />
      </geometry>
    </collision>
  </link>
  <joint
    name="wrist_3_joint"
    type="revolute">
    <origin
      xyz="-0.055073 0.0089909 0.17061"
      rpy="-1.5708 0 1.4264" />
    <parent
      link="wrist_2_link" />
    <child
      link="wrist_3_link" />
    <axis
      xyz="0 0 1" />
    <limit
      lower="0"
      upper="3.142"
      effort="50"
      velocity="2" />
  </joint>
</robot>