<?xml version="1.0" encoding="utf-8"?>
<!-- This URDF was automatically created by SolidWorks to URDF Exporter! Originally created by Stephen Brawner (brawner@gmail.com) 
     Commit Version: 1.6.0-4-g7f85cfe  Build Version: 1.6.7995.38578
     For more information, please see http://wiki.ros.org/sw_urdf_exporter -->
<robot
  name="realll_urdf">
  <link
    name="base_link">
    <inertial>
      <origin
        xyz="0.00047472 6.9315E-06 0.018436"
        rpy="0 0 0" />
      <mass
        value="0.70951" />
      <inertia
        ixx="0.0011478"
        ixy="-4.6822E-08"
        ixz="-2.9441E-07"
        iyy="0.0011755"
        iyz="7.868E-08"
        izz="0.0021505" />
    </inertial>
    <visual>
      <origin
        xyz="0 0 0"
        rpy="0 0 0" />
      <geometry>
        <mesh
          filename="package://realll_urdf/meshes/base_link.STL" />
      </geometry>
      <material
        name="">
        <color
          rgba="0.75686 0.76863 0.75294 1" />
      </material>
    </visual>
    <collision>
      <origin
        xyz="0 0 0"
        rpy="0 0 0" />
      <geometry>
        <mesh
          filename="package://realll_urdf/meshes/base_link.STL" />
      </geometry>
    </collision>
  </link>
  <link
    name="Link_1">
    <inertial>
      <origin
        xyz="0.0023542 0.0085726 0.12447"
        rpy="0 0 0" />
      <mass
        value="3.4311" />
      <inertia
        ixx="0.011117"
        ixy="-0.0001688"
        ixz="-0.0002995"
        iyy="0.010549"
        iyz="-0.0010909"
        izz="0.010872" />
    </inertial>
    <visual>
      <origin
        xyz="0 0 0"
        rpy="0 0 0" />
      <geometry>
        <mesh
          filename="package://realll_urdf/meshes/Link_1.STL" />
      </geometry>
      <material
        name="">
        <color
          rgba="0.75686 0.76863 0.75294 1" />
      </material>
    </visual>
    <collision>
      <origin
        xyz="0 0 0"
        rpy="0 0 0" />
      <geometry>
        <mesh
          filename="package://realll_urdf/meshes/Link_1.STL" />
      </geometry>
    </collision>
  </link>
  <joint
    name="Joint_1"
    type="revolute">
    <origin
      xyz="0 0 0"
      rpy="0 0 0" />
    <parent
      link="base_link" />
    <child
      link="Link_1" />
    <axis
      xyz="0 0 1" />
    <limit
      lower="0"
      upper="3.142"
      effort="300"
      velocity="3" />
  </joint>
  <link
    name="Link_2">
    <inertial>
      <origin
        xyz="4.1795E-07 -0.076521 0.14802"
        rpy="0 0 0" />
      <mass
        value="1.5487" />
      <inertia
        ixx="0.002778"
        ixy="-4.2325E-09"
        ixz="2.0685E-08"
        iyy="0.0026285"
        iyz="-0.00038502"
        izz="0.00292" />
    </inertial>
    <visual>
      <origin
        xyz="0 0 0"
        rpy="0 0 0" />
      <geometry>
        <mesh
          filename="package://realll_urdf/meshes/Link_2.STL" />
      </geometry>
      <material
        name="">
        <color
          rgba="0.75686 0.76863 0.75294 1" />
      </material>
    </visual>
    <collision>
      <origin
        xyz="0 0 0"
        rpy="0 0 0" />
      <geometry>
        <mesh
          filename="package://realll_urdf/meshes/Link_2.STL" />
      </geometry>
    </collision>
  </link>
  <joint
    name="Joint_2"
    type="revolute">
    <origin
      xyz="0.00081755 0.002978 0.21171"
      rpy="1.5708 0 2.8737" />
    <parent
      link="Link_1" />
    <child
      link="Link_2" />
    <axis
      xyz="0 0 1" />
    <limit
      lower="-1.57"
      upper="1.57"
      effort="200"
      velocity="3" />
  </joint>
  <link
    name="Link_3">
    <inertial>
      <origin
        xyz="0.0016204 0.00038775 -0.063393"
        rpy="0 0 0" />
      <mass
        value="1.4714" />
      <inertia
        ixx="0.0023471"
        ixy="3.5886E-09"
        ixz="-0.0003313"
        iyy="0.002487"
        iyz="-2.0842E-08"
        izz="0.0027804" />
    </inertial>
    <visual>
      <origin
        xyz="0 0 0"
        rpy="0 0 0" />
      <geometry>
        <mesh
          filename="package://realll_urdf/meshes/Link_3.STL" />
      </geometry>
      <material
        name="">
        <color
          rgba="0.75686 0.76863 0.75294 1" />
      </material>
    </visual>
    <collision>
      <origin
        xyz="0 0 0"
        rpy="0 0 0" />
      <geometry>
        <mesh
          filename="package://realll_urdf/meshes/Link_3.STL" />
      </geometry>
    </collision>
  </link>
  <joint
    name="Joint_3"
    type="revolute">
    <origin
      xyz="-0.013053 0.4998 -0.04121"
      rpy="-3.1416 -0.034793 3.1416" />
    <parent
      link="Link_2" />
    <child
      link="Link_3" />
    <axis
      xyz="0 0 -1" />
    <limit
      lower="-1.57"
      upper="1.57"
      effort="200"
      velocity="3" />
  </joint>
  <link
    name="Link_4">
    <inertial>
      <origin
        xyz="0.038757 0.0032123 -0.16106"
        rpy="0 0 0" />
      <mass
        value="0.83842" />
      <inertia
        ixx="0.0010339"
        ixy="-3.0338E-05"
        ixz="1.6348E-05"
        iyy="0.0009644"
        iyz="0.00012774"
        izz="0.00096895" />
    </inertial>
    <visual>
      <origin
        xyz="0 0 0"
        rpy="0 0 0" />
      <geometry>
        <mesh
          filename="package://realll_urdf/meshes/Link_4.STL" />
      </geometry>
      <material
        name="">
        <color
          rgba="0.75686 0.76863 0.75294 1" />
      </material>
    </visual>
    <collision>
      <origin
        xyz="0 0 0"
        rpy="0 0 0" />
      <geometry>
        <mesh
          filename="package://realll_urdf/meshes/Link_4.STL" />
      </geometry>
    </collision>
  </link>
  <joint
    name="Joint_4"
    type="revolute">
    <origin
      xyz="0.56474 0.000388 -0.0090716"
      rpy="0 0.23313 0" />
    <parent
      link="Link_3" />
    <child
      link="Link_4" />
    <axis
      xyz="-0.23103 0 0.97295" />
    <limit
      lower="-1.57"
      upper="1.57"
      effort="200"
      velocity="3" />
  </joint>
  <link
    name="Link_5">
    <inertial>
      <origin
        xyz="0.0034039 0.00048525 0.16585"
        rpy="0 0 0" />
      <mass
        value="0.83842" />
      <inertia
        ixx="0.00096592"
        ixy="1.045E-05"
        ixz="-0.00012992"
        iyy="0.0010363"
        iyz="1.8899E-05"
        izz="0.00096507" />
    </inertial>
    <visual>
      <origin
        xyz="0 0 0"
        rpy="0 0 0" />
      <geometry>
        <mesh
          filename="package://realll_urdf/meshes/Link_5.STL" />
      </geometry>
      <material
        name="">
        <color
          rgba="0.75686 0.76863 0.75294 1" />
      </material>
    </visual>
    <collision>
      <origin
        xyz="0 0 0"
        rpy="0 0 0" />
      <geometry>
        <mesh
          filename="package://realll_urdf/meshes/Link_5.STL" />
      </geometry>
    </collision>
  </link>
  <joint
    name="Joint_5"
    type="revolute">
    <origin
      xyz="0.039855 -0.05588 -0.16569"
      rpy="-1.5708 0 0" />
    <parent
      link="Link_4" />
    <child
      link="Link_5" />
    <axis
      xyz="0 0 -1" />
    <limit
      lower="-1.57"
      upper="1.57"
      effort="100"
      velocity="2" />
  </joint>
  <link
    name="Link_6">
    <inertial>
      <origin
        xyz="0.00017986 -4.4952E-05 -0.13062"
        rpy="0 0 0" />
      <mass
        value="0.15932" />
      <inertia
        ixx="8.2239E-05"
        ixy="1.0723E-06"
        ixz="8.7279E-08"
        iyy="8.7571E-05"
        iyz="4.5096E-07"
        izz="0.00014976" />
    </inertial>
    <visual>
      <origin
        xyz="0 0 0"
        rpy="0 0 0" />
      <geometry>
        <mesh
          filename="package://realll_urdf/meshes/Link_6.STL" />
      </geometry>
      <material
        name="">
        <color
          rgba="0.75686 0.76863 0.75294 1" />
      </material>
    </visual>
    <collision>
      <origin
        xyz="0 0 0"
        rpy="0 0 0" />
      <geometry>
        <mesh
          filename="package://realll_urdf/meshes/Link_6.STL" />
      </geometry>
    </collision>
  </link>
  <joint
    name="Joint_6"
    type="revolute">
    <origin
      xyz="-0.055073 0.0089909 0.17061"
      rpy="-1.5708 0 1.4264" />
    <parent
      link="Link_5" />
    <child
      link="Link_6" />
    <axis
      xyz="0 0 1" />
    <limit
      lower="0"
      upper="3.142"
      effort="50"
      velocity="2" />
  </joint>
</robot>